{
  "comments": [
    {
      "unresolved": true,
      "key": {
        "uuid": "5b826bc9_d3dd9096",
        "filename": "/COMMIT_MSG",
        "patchSetId": 3
      },
      "lineNbr": 14,
      "author": {
        "id": 97483
      },
      "writtenOn": "2022-03-20T16:55:08Z",
      "side": 1,
      "message": "I don\u0027t think so: if an exception is thrown at L97 you end up in the finally block where the exception can be swallowed if a new TransportException is thrown again.",
      "range": {
        "startLine": 13,
        "startChar": 29,
        "endLine": 14,
        "endChar": 20
      },
      "revId": "4194913e696d4dd674299d15dd3b4df782ca05f7",
      "serverId": "97ee7c02-f12f-4043-b43e-dea463d88b31"
    },
    {
      "unresolved": true,
      "key": {
        "uuid": "1e23efeb_fcb30850",
        "filename": "/COMMIT_MSG",
        "patchSetId": 3
      },
      "lineNbr": 14,
      "author": {
        "id": 241433
      },
      "writtenOn": "2022-03-22T08:30:31Z",
      "side": 1,
      "message": "With the current code the only exception that can be Thrown is an IOException at L103. Not sure I understand how we could throw a TransportException.",
      "parentUuid": "5b826bc9_d3dd9096",
      "range": {
        "startLine": 13,
        "startChar": 29,
        "endLine": 14,
        "endChar": 20
      },
      "revId": "4194913e696d4dd674299d15dd3b4df782ca05f7",
      "serverId": "97ee7c02-f12f-4043-b43e-dea463d88b31"
    },
    {
      "unresolved": true,
      "key": {
        "uuid": "945af980_6e2959e3",
        "filename": "/COMMIT_MSG",
        "patchSetId": 3
      },
      "lineNbr": 14,
      "author": {
        "id": 97483
      },
      "writtenOn": "2022-03-22T21:59:13Z",
      "side": 1,
      "message": "I\u0027ve commented in the code the swallowed exception.",
      "parentUuid": "1e23efeb_fcb30850",
      "range": {
        "startLine": 13,
        "startChar": 29,
        "endLine": 14,
        "endChar": 20
      },
      "revId": "4194913e696d4dd674299d15dd3b4df782ca05f7",
      "serverId": "97ee7c02-f12f-4043-b43e-dea463d88b31"
    },
    {
      "unresolved": true,
      "key": {
        "uuid": "55d5f90f_26031fed",
        "filename": "org.eclipse.jgit/src/org/eclipse/jgit/transport/FetchProcess.java",
        "patchSetId": 3
      },
      "lineNbr": 97,
      "author": {
        "id": 97483
      },
      "writtenOn": "2022-03-22T21:59:13Z",
      "side": 1,
      "message": "When throwing this exception, the code will continue on L100. If an IOException is thrown again, the original \u0027err\u0027 will be swallowed.",
      "range": {
        "startLine": 97,
        "startChar": 3,
        "endLine": 97,
        "endChar": 13
      },
      "revId": "4194913e696d4dd674299d15dd3b4df782ca05f7",
      "serverId": "97ee7c02-f12f-4043-b43e-dea463d88b31"
    },
    {
      "unresolved": true,
      "key": {
        "uuid": "476abc4f_d7b3087c",
        "filename": "org.eclipse.jgit/src/org/eclipse/jgit/transport/FetchProcess.java",
        "patchSetId": 3
      },
      "lineNbr": 97,
      "author": {
        "id": 97483
      },
      "writtenOn": "2022-03-24T09:40:49Z",
      "side": 1,
      "message": "Actually this is managed at L104. However, other non-checked exception may happen (e.g. timeouts, other IO errors) and those would risk to be 100% swallowed.",
      "parentUuid": "55d5f90f_26031fed",
      "range": {
        "startLine": 97,
        "startChar": 3,
        "endLine": 97,
        "endChar": 13
      },
      "revId": "4194913e696d4dd674299d15dd3b4df782ca05f7",
      "serverId": "97ee7c02-f12f-4043-b43e-dea463d88b31"
    },
    {
      "unresolved": true,
      "key": {
        "uuid": "8f25035a_78d96a0b",
        "filename": "org.eclipse.jgit/src/org/eclipse/jgit/transport/FetchProcess.java",
        "patchSetId": 3
      },
      "lineNbr": 97,
      "author": {
        "id": 241433
      },
      "writtenOn": "2022-03-25T09:01:21Z",
      "side": 1,
      "message": "Good point. @Matthias: looks like this was introduced in https://git.eclipse.org/r/c/jgit/jgit/+/2055\n\nAre we missing something or it is actually possible that we could end up swallowing the exception?",
      "parentUuid": "476abc4f_d7b3087c",
      "range": {
        "startLine": 97,
        "startChar": 3,
        "endLine": 97,
        "endChar": 13
      },
      "revId": "4194913e696d4dd674299d15dd3b4df782ca05f7",
      "serverId": "97ee7c02-f12f-4043-b43e-dea463d88b31"
    }
  ]
}