{
  "comments": [
    {
      "key": {
        "uuid": "87929364_d1c4728a",
        "filename": "pom.xml",
        "patchSetId": 2
      },
      "lineNbr": 576,
      "author": {
        "id": 925
      },
      "writtenOn": "2017-12-21T06:30:43Z",
      "side": 1,
      "message": "Shouldn\u0027t this be true if we\u0027re re-enabling failure as described in the commit message?",
      "range": {
        "startLine": 576,
        "startChar": 23,
        "endLine": 576,
        "endChar": 28
      },
      "revId": "db80c08c54066bfbd7b7f5238704bc1b686c17c8",
      "serverId": "97ee7c02-f12f-4043-b43e-dea463d88b31",
      "unresolved": false
    }
  ]
}